4.1.2 2024-02-06 16:00:01,994 INFO 139747197847360 - Starting to get apps
4.1.2 2024-02-06 16:00:02,411 ERROR 139747197847360 - Could not make request to Splunk: [HTTP 404] https://127.0.0.1:8089/services/pura_app_list?type=deployment
Traceback (most recent call last):
  File "/opt/splunk/etc/apps/python_upgrade_readiness_app/bin/pura_remote_latest_report.py", line 137, in get_all_apps
    response, content = sr.simpleRequest(path=endpoint, sessionKey=self.session_key, method="GET")
  File "/opt/splunk/lib/python3.7/site-packages/splunk/rest/__init__.py", line 661, in simpleRequest
    raise splunk.ResourceNotFound(uri)
splunk.ResourceNotFound: [HTTP 404] https://127.0.0.1:8089/services/pura_app_list?type=deployment
4.1.2 2024-02-06 16:00:02,584 INFO 139747197847360 - merged_file_path = /opt/splunk/etc/apps/python_upgrade_readiness_app/local/merged/merged_report.json
4.1.2 2024-02-06 16:00:02,584 INFO 139747197847360 - Writing local report as merged report could not be generated.
4.1.2 2024-02-06 16:00:02,584 INFO 139747197847360 - splunk-system-user file does not exists.
