4.1.2 2024-02-06 07:00:01,045 INFO 140188423649088 - Could not find synced splunkbase apps so using the constant file
4.1.2 2024-02-06 07:00:01,046 INFO 140188423649088 - splunkbase_path- /opt/splunk/etc/apps/python_upgrade_readiness_app/bin/libs_py3/pura_libs_utils/splunkbaseapps.csv
4.1.2 2024-02-06 07:00:01,072 INFO 140188423649088 - Starting to get apps
4.1.2 2024-02-06 07:00:01,671 ERROR 140188423649088 - Could not make request to Splunk: [HTTP 404] https://127.0.0.1:8089/services/pura_app_list?type=deployment
Traceback (most recent call last):
  File "/opt/splunk/etc/apps/python_upgrade_readiness_app/bin/jura_remote_latest_report.py", line 229, in get_all_apps
    response, content = sr.simpleRequest(path=endpoint, sessionKey=self.session_key, method="GET")
  File "/opt/splunk/lib/python3.7/site-packages/splunk/rest/__init__.py", line 661, in simpleRequest
    raise splunk.ResourceNotFound(uri)
splunk.ResourceNotFound: [HTTP 404] https://127.0.0.1:8089/services/pura_app_list?type=deployment
4.1.2 2024-02-06 07:00:01,842 INFO 140188423649088 - merged_file_path = /opt/splunk/etc/apps/python_upgrade_readiness_app/local/jquery_merged/merged_report.json
4.1.2 2024-02-06 07:00:01,842 INFO 140188423649088 - Writing local report as merged report could not be generated.
4.1.2 2024-02-06 07:00:01,842 INFO 140188423649088 - splunk-system-user file does not exists.
4.1.2 2024-02-06 19:00:02,073 INFO 140220156290880 - Could not find synced splunkbase apps so using the constant file
4.1.2 2024-02-06 19:00:02,078 INFO 140220156290880 - splunkbase_path- /opt/splunk/etc/apps/python_upgrade_readiness_app/bin/libs_py3/pura_libs_utils/splunkbaseapps.csv
4.1.2 2024-02-06 19:00:02,141 INFO 140220156290880 - Starting to get apps
4.1.2 2024-02-06 19:00:02,797 ERROR 140220156290880 - Could not make request to Splunk: [HTTP 404] https://127.0.0.1:8089/services/pura_app_list?type=deployment
Traceback (most recent call last):
  File "/opt/splunk/etc/apps/python_upgrade_readiness_app/bin/jura_remote_latest_report.py", line 229, in get_all_apps
    response, content = sr.simpleRequest(path=endpoint, sessionKey=self.session_key, method="GET")
  File "/opt/splunk/lib/python3.7/site-packages/splunk/rest/__init__.py", line 661, in simpleRequest
    raise splunk.ResourceNotFound(uri)
splunk.ResourceNotFound: [HTTP 404] https://127.0.0.1:8089/services/pura_app_list?type=deployment
4.1.2 2024-02-06 19:00:03,495 INFO 140220156290880 - merged_file_path = /opt/splunk/etc/apps/python_upgrade_readiness_app/local/jquery_merged/merged_report.json
4.1.2 2024-02-06 19:00:03,496 INFO 140220156290880 - remote_file_path = /opt/splunk/etc/apps/python_upgrade_readiness_app/local/jquery_remote/GOEL-ClusterMaster.json
4.1.2 2024-02-06 19:00:03,496 INFO 140220156290880 - Skipping to write report from indexer: GOEL-ClusterMaster as it is empty.Trying to fetch result from another indexer
4.1.2 2024-02-06 19:00:03,496 INFO 140220156290880 - remote_file_path = /opt/splunk/etc/apps/python_upgrade_readiness_app/local/jquery_remote/GOEL-SearchHead.json
4.1.2 2024-02-06 19:00:03,496 INFO 140220156290880 - Skipping to write report from indexer: GOEL-SearchHead as it is empty.Trying to fetch result from another indexer
4.1.2 2024-02-06 19:00:03,496 INFO 140220156290880 - Writing local report as merged report could not be generated.
4.1.2 2024-02-06 19:00:03,496 INFO 140220156290880 - splunk-system-user file does not exists.
