4.1.2 2024-02-06 04:00:02,782 INFO 140109247051584 - Starting to get apps
4.1.2 2024-02-06 04:00:04,228 ERROR 140109247051584 - Could not make request to Splunk: [HTTP 404] https://127.0.0.1:8089/services/pura_app_list?type=deployment
Traceback (most recent call last):
  File "/opt/splunk/etc/apps/python_upgrade_readiness_app/bin/pura_remote_latest_report.py", line 137, in get_all_apps
    response, content = sr.simpleRequest(path=endpoint, sessionKey=self.session_key, method="GET")
  File "/opt/splunk/lib/python3.7/site-packages/splunk/rest/__init__.py", line 661, in simpleRequest
    raise splunk.ResourceNotFound(uri)
splunk.ResourceNotFound: [HTTP 404] https://127.0.0.1:8089/services/pura_app_list?type=deployment
4.1.2 2024-02-06 04:00:04,706 INFO 140109247051584 - merged_file_path = /opt/splunk/etc/apps/python_upgrade_readiness_app/local/merged/merged_report.json
4.1.2 2024-02-06 04:00:04,706 INFO 140109247051584 - Writing local report as merged report could not be generated.
4.1.2 2024-02-06 04:00:04,706 INFO 140109247051584 - splunk-system-user file does not exists.
4.1.2 2024-02-06 16:00:01,722 INFO 139726886131520 - Starting to get apps
4.1.2 2024-02-06 16:00:03,717 ERROR 139726886131520 - Could not make request to Splunk: [HTTP 404] https://127.0.0.1:8089/services/pura_app_list?type=deployment
Traceback (most recent call last):
  File "/opt/splunk/etc/apps/python_upgrade_readiness_app/bin/pura_remote_latest_report.py", line 137, in get_all_apps
    response, content = sr.simpleRequest(path=endpoint, sessionKey=self.session_key, method="GET")
  File "/opt/splunk/lib/python3.7/site-packages/splunk/rest/__init__.py", line 661, in simpleRequest
    raise splunk.ResourceNotFound(uri)
splunk.ResourceNotFound: [HTTP 404] https://127.0.0.1:8089/services/pura_app_list?type=deployment
4.1.2 2024-02-06 16:00:04,300 INFO 139726886131520 - merged_file_path = /opt/splunk/etc/apps/python_upgrade_readiness_app/local/merged/merged_report.json
4.1.2 2024-02-06 16:00:04,301 INFO 139726886131520 - remote_file_path = /opt/splunk/etc/apps/python_upgrade_readiness_app/local/remote/GOEL-ClusterMaster.json
4.1.2 2024-02-06 16:00:04,301 INFO 139726886131520 - Skipping to write report from indexer: GOEL-ClusterMaster as it is empty.Trying to fetch result from another indexer
4.1.2 2024-02-06 16:00:04,301 INFO 139726886131520 - remote_file_path = /opt/splunk/etc/apps/python_upgrade_readiness_app/local/remote/GOEL-SearchHead.json
4.1.2 2024-02-06 16:00:04,301 INFO 139726886131520 - Skipping to write report from indexer: GOEL-SearchHead as it is empty.Trying to fetch result from another indexer
4.1.2 2024-02-06 16:00:04,301 INFO 139726886131520 - Writing local report as merged report could not be generated.
4.1.2 2024-02-06 16:00:04,301 INFO 139726886131520 - splunk-system-user file does not exists.
